Workbook

Sheet 直企P1(列印)
G1: ＊ 107.09.26 簽核版本
A2: 國立成功大學 登山協會 | D2: 茶茶牙頓出西都驕溪 | F2: 登山活動計劃書
A3: 活動日期 | C3: 自 民國 115 年 4 月 30 日 20 時 | F3: 入山：臺東縣達仁鄉
C4: 至 民國 115 年 5 月 3 日 15 時，共計 3 日 3 夜 | F4: 出山：屏東縣獅子鄉
A5: 隊伍性質 | C5: 級數： D 級隊 | E5: 性質： 探勘隊 | F5: ="共 計 17 人" -> 共 計 17 人
C6: (協會法規) 幹部 3 人 / 隊員 6 人 / 非隊員 8 人 | F6: ="男 9 人 - 女 8 人" -> 男 9 人 - 女 8 人
A7: 行程表 | B7: 糧食： 3 日份 | E7: 備糧： 1 日份 | F7: 水源 | G7: 通訊
B8: 4/30 D0： | C8: 成大光口→加羅坂部落→浸水營古道東段登山口 C0 | F8: O (大武溪) | G8: O
B9: 5/1 D1： | C9: C0→上溯大武溪溪床→大武溪溪底登山口H200→茶茶牙頓駐在所H470→茶茶牙頓社→落葉營地H716→寬稜營地H850 C1 | F9: X | G9: X
B10: 5/2 D2： | C10: C1→P1075峰→P1325茶茶牙頓山→小空地營地H1143→茶茶牙頓山鐵牌→石壁水源H520→新都驕溪河灘營地 C2 | F10: O (新都驕溪) | G10: X
B11: 5/3 D3： | C11: C2→西都驕溪溪床登山口 | F11: O (西都驕溪) | G11: X
B12: 撤退路線： | C12: 出隊期間有颱風警報、公路斷掉，則倒隊。 茶茶牙頓山前原路撤退出大武溪溪床(姑仔崙吊橋)，過茶茶牙頓山後則加速往西都驕溪撤出。 | F12: 附件：地圖與路線
B14: 轉進路線： | C14: 若P1075峰至茶茶牙頓山之間探勘路窒礙難行，D2原路撤回大武溪溪底登山口，D3上溯茶茶牙頓溪後上正南稜接浸水營古道出大漢林道。
B15: 保險時間： | C15: 115 年 4 月 30 日 20 時至 115 年 5 月 3 日 20 時 | F15: 預備天： 1 天
A16: 工作人員 | C16: 姓 名 | D16: 電 話 | E16: 資 料 | F16: 嚮導簽章
B17: 主持人 | C17: 程效賢 | D17: 0939952841 | E17: 土木114 (OB)
B18: 留 守 | C18: 宋張齊 | D18: 0906532363 | E18: 醫藥：楊育銘 | F18: 保險：張仁熏
E19: 裝備：宋侑達 | F19: 紀錄總整：新生
E20: 公文：傅琨鋮、劉祐任、邱以昕 | F20: 入山：郭佳宛
B21: 領 隊 | C21: 程效賢 | D21: 0939952841 | E21: 大廚：張婷萱、邱于馨 | F21: 剪片：吳琇如
B22: 嚮 導 | C22: 宋侑達 | D22: 0966139234 | E22: 二廚：陳莉臻、李思誼 | F22: 包車：陳柏亨
A23: 行前會 | C23: 日期 | D23: 地點 | E23: 項目
B24: 第一次 | C24: 2026/4/23 2026/4/24 | D24: 線上 | E24: 隊伍分工、行前教育、行程解說
B25: - | C25: - | D25: 自行訓練
B26: 第二次 | D26: 社辦 | E26: 分公裝食材、檢查地圖記錄、蜂螫蛇咬迷途
G29: ＊ 下表由成大山協內部流程使用
A30: 幹部群長 | C30: 幹部群 | D30: 審核留言 | E30: 總務 | F30: 指導老師
E31: ="= 50 * 16人 * "&COUNTA(B9:B11)&"夜"&char(10)&"= 山防費 $ 2400" -> = 50 * 16人 * 3夜 = 山防費 $ 2400
A32: 山防組長
F33: (06) 270 2082 0920 842 015

Sheet 直企P2(列印)
B1: ='直企P1(列印)'!D2 -> 茶茶牙頓出西都驕溪
B2: 裝 備 表 | M2: 留 守 資 料
B3: 公共裝備 | C3: 四人帳棚 | D3: 0 | E3: 衛星電話 | F3: 0 | G3: 爐頭 | H3: 4 | I3: 技術裝備 | J3: 團體 | K3: 20米扁+2D | L3: 1 | M3: 交通方式 | N3: 來回九人座*2
C4: 10人雨布 | D4: 2 | E4: 高度計 | F4: 0 | G4: 瓦斯 | H4: 4 | M4: 司機電話 | N4: 黑皮大哥
C5: 地紙(L) | D5: 8 | E5: 無線電 | F5: 4 | G5: 鍋/瓢/蓋 | H5: 4
C6: 營釘 | D6: 16 | E6: 路標(捆) | F6: 2 | G6: 山刀 | H6: 3 | M6: 頻道台號 | N6: 144.280
C7: 營繩 | D7: 16 | E7: 收音機 | F7: 0 | G7: 枝剪 | H7: 2 | J7: 個人 | K7: 岩盔 | L7: 1 | M7: 衛星電話 | N7: Garmin inReach mini 2
C8: 醫藥箱 | D8: 2 | E8: garmin2 | F8: 1 | G8: 鋸子 | H8: 2 | K8: 溯溪鞋 | L8: 1 | M8: 開機時間 | N8: 0.83333333
C9: 鋁箔棉手套 | D9: 2 | E9: 登山杖 | F9: 4 | G9: 鋁箔 | K9: 丟露宿裝備 | L9: 1
B10: 其他備註： | D10: https://share.garmin.com/sttsgarmin
B11: 注意事項： | D11: 黃藤等刺刺植物多 輕裝包 背包防水!! 公水：空水罐1.5L+行進水 | M11: 李老師 | N11: 0920 842 015
O13: ＊ 若欄位不足請自行延伸
B14: 人員資料
B15: 學號 系級 | D15: 姓名 電話 | F15: 級數 資歷 | H15: 身分證字號 生日 | K15: 緊急聯絡人(關係) 電話 | M15: 血型 | N15: 藥物 過敏 | O15: 未成年 < 18
A16: 領 | B16: ='人員資料表'!K5&CHAR(10)&'人員資料表'!L5 -> 土木114 E64102038 | D16: ='人員資料表'!E5&CHAR(10)&'人員資料表'!J5 -> 程效賢 0939952841 | F16: ='人員資料表'!G5 -> A/奇萊東稜下嵐山 | H16: ='人員資料表'!M5&CHAR(10)&TEXT('人員資料表'!N5,"yyyy/mm/dd") -> F131195218 2002/09/17 | K16: ='人員資料表'!P5&CHAR(10)&'人員資料表'!Q5 -> 金愛君（母子） 0952952841 | M16: ='人員資料表'!S5 -> B | N16: ='人員資料表'!T5 -> NKDA
A17: 嚮 | B17: ='人員資料表'!K6&CHAR(10)&'人員資料表'!L6 -> 水利114 E84104034 | D17: ='人員資料表'!E6&CHAR(10)&'人員資料表'!J6 -> 宋侑達 0966139234 | F17: ='人員資料表'!G6 -> B活/大壩聖稜 | H17: ='人員資料表'!M6&CHAR(10)&TEXT('人員資料表'!N6,"yyyy/mm/dd") -> L125840395 2002/12/01 | K17: ='人員資料表'!P6&CHAR(10)&'人員資料表'!Q6 -> 宋坤龍（父子） 0928542036 | M17: ='人員資料表'!S6 -> A | N17: ='人員資料表'!T6 -> NKDA
A18: 隊 | B18: ='人員資料表'!K7&CHAR(10)&'人員資料表'!L7 -> 地科114 C44106206 | D18: ='人員資料表'!E7&CHAR(10)&'人員資料表'!J7 -> 陳柏亨 0905377012 | F18: ='人員資料表'!G7 -> 12A 童話嘆息 | H18: ='人員資料表'!M7&CHAR(10)&TEXT('人員資料表'!N7,"yyyy/mm/dd") -> E125475393 2003/05/29 | K18: ='人員資料表'!P7&CHAR(10)&'人員資料表'!Q7 -> 張文瀞（母子） 0929331445 | M18: ='人員資料表'!S7 -> B | N18: ='人員資料表'!T7 -> 無
B19: ='人員資料表'!K8&CHAR(10)&'人員資料表'!L8 -> 牙醫115 I94096024 | D19: ='人員資料表'!E8&CHAR(10)&'人員資料表'!J8 -> 張薰慈 0976818408 | F19: ='人員資料表'!G8 -> A/知本林鐵 | H19: ='人員資料表'!M8&CHAR(10)&TEXT('人員資料表'!N8,"yyyy/mm/dd") -> F230782791 2001/10/20 | K19: ='人員資料表'!P8&CHAR(10)&'人員資料表'!Q8 -> 徐碧卿（母女） 0976533082 | M19: ='人員資料表'!S8 -> O | N19: ='人員資料表'!T8 -> 無
B20: ='人員資料表'!K9&CHAR(10)&'人員資料表'!L9 -> 資訊115 AN4116063 | D20: ='人員資料表'!E9&CHAR(10)&'人員資料表'!J9 -> 陳莉臻 0905574912 | F20: ='人員資料表'!G9 -> B/剩餞 | H20: ='人員資料表'!M9&CHAR(10)&TEXT('人員資料表'!N9,"yyyy/mm/dd") -> O200644071 2004/02/27 | K20: ='人員資料表'!P9&CHAR(10)&'人員資料表'!Q9 -> 張雅惠（母女） 0922313887 | M20: ='人員資料表'!S9 -> AB | N20: ='人員資料表'!T9 -> NKDA
B21: ='人員資料表'!K10&CHAR(10)&'人員資料表'!L10 -> 心理117 D84136014 | D21: ='人員資料表'!E10&CHAR(10)&'人員資料表'!J10 -> 張仁熏 0912683511 | F21: ='人員資料表'!G10 -> A/知本林鐵 | H21: ='人員資料表'!M10&CHAR(10)&TEXT('人員資料表'!N10,"yyyy/mm/dd") -> A132077143 2006/05/08 | K21: ='人員資料表'!P10&CHAR(10)&'人員資料表'!Q10 -> 蔡茵如（母子） 0921308802 | M21: ='人員資料表'!S10 -> O | N21: ='人員資料表'!T10 -> 無
B22: ='人員資料表'!K11&CHAR(10)&'人員資料表'!L11 -> 生科碩二 L56134166 | D22: ='人員資料表'!E11&CHAR(10)&'人員資料表'!J11 -> 曾翔鈺 0926801336 | F22: ='人員資料表'!G11 -> 8B/丹大溫泉 | H22: ='人員資料表'!M11&CHAR(10)&TEXT('人員資料表'!N11,"yyyy/mm/dd") -> A230567431 2001/06/29 | K22: ='人員資料表'!P11&CHAR(10)&'人員資料表'!Q11 -> 曾厚勳（父女） 0927238063 | M22: ='人員資料表'!S11 -> B | N22: ='人員資料表'!T11 -> NKDA
B23: ='人員資料表'!K12&CHAR(10)&'人員資料表'!L12 -> 建研所 E74096035 | D23: ='人員資料表'!E12&CHAR(10)&'人員資料表'!J12 -> 李思誼 0985204657 | F23: ='人員資料表'!G12 -> 8B勘/巴冷公主撞月樹 | H23: ='人員資料表'!M12&CHAR(10)&TEXT('人員資料表'!N12,"yyyy/mm/dd") -> F230379909 2001/11/19 | K23: ='人員資料表'!P12&CHAR(10)&'人員資料表'!Q12 -> 李昭俊（父女） 0922023106 | M23: ='人員資料表'!S12 -> O | N23: ='人員資料表'!T12 -> NKDA
B24: ='人員資料表'!K13&CHAR(10)&'人員資料表'!L13 -> 資源所112 N46114213 | D24: ='人員資料表'!E13&CHAR(10)&'人員資料表'!J13 -> 楊育銘 0986873262 | F24: ='人員資料表'!G13 -> C活/西拉歐卡 | H24: ='人員資料表'!M13&CHAR(10)&TEXT('人員資料表'!N13,"yyyy/mm/dd") -> A127342866 1999/08/20 | K24: ='人員資料表'!P13&CHAR(10)&'人員資料表'!Q13 -> 楊定恭（父子） 0963278285 | M24: ='人員資料表'!S13 -> O | N24: ='人員資料表'!T13 -> NKDA
A25: 新 | B25: ='人員資料表'!K14&CHAR(10)&'人員資料表'!L14 -> 土木118 E64141090 | D25: ='人員資料表'!E14&CHAR(10)&'人員資料表'!J14 -> 邱以昕 0978001281 | F25: ='人員資料表'!G14 -> C/忘了 | H25: ='人員資料表'!M14&CHAR(10)&TEXT('人員資料表'!N14,"yyyy/mm/dd") -> A132065296 2007/07/29 | K25: ='人員資料表'!P14&CHAR(10)&'人員資料表'!Q14 -> 邱威凱（父子） 0972811139 | M25: ='人員資料表'!S14 -> O | N25: ='人員資料表'!T14 -> NKDA
B26: ='人員資料表'!K15&CHAR(10)&'人員資料表'!L15 -> 航太118 F44141151 | D26: ='人員資料表'!E15&CHAR(10)&'人員資料表'!J15 -> 劉祐任 0934212106 | F26: ='人員資料表'!G15 -> D/大眾化白雪村採樟腦 | H26: ='人員資料表'!M15&CHAR(10)&TEXT('人員資料表'!N15,"yyyy/mm/dd") -> N126883789 2006/02/20 | K26: ='人員資料表'!P15&CHAR(10)&'人員資料表'!Q15 -> 劉玠庭（父子） 0953080665 | M26: ='人員資料表'!S15 -> O | N26: ='人員資料表'!T15 -> 無NKDA
B27: ='人員資料表'!K16&CHAR(10)&'人員資料表'!L16 -> 台文118 B54144726 | D27: ='人員資料表'!E16&CHAR(10)&'人員資料表'!J16 -> 郭佳宛 0906871119 | F27: ='人員資料表'!G16 -> C/萬山岩雕 | H27: ='人員資料表'!M16&CHAR(10)&TEXT('人員資料表'!N16,"yyyy/mm/dd") -> N226495432 2006/11/09 | K27: ='人員資料表'!P16&CHAR(10)&'人員資料表'!Q16 -> 劉婉慧（母女） 0918879151 | M27: ='人員資料表'!S16 -> A | N27: ='人員資料表'!T16 -> NKDA
B28: ='人員資料表'!K17&CHAR(10)&'人員資料表'!L17 -> 生科碩一 L56144137 | D28: ='人員資料表'!E17&CHAR(10)&'人員資料表'!J17 -> 蔡岳承 0909323691 | F28: ='人員資料表'!G17 -> D勘/蛟龍爬去哪 | H28: ='人員資料表'!M17&CHAR(10)&TEXT('人員資料表'!N17,"yyyy/mm/dd") -> B123726590 2002/05/27 | K28: ='人員資料表'!P17&CHAR(10)&'人員資料表'!Q17 -> 蔡至強（父子） 0923309046 | M28: ='人員資料表'!S17 -> O | N28: ='人員資料表'!T17 -> 無
B29: ='人員資料表'!K18&CHAR(10)&'人員資料表'!L18 -> 心理117 D84134020 | D29: ='人員資料表'!E18&CHAR(10)&'人員資料表'!J18 -> 張婷萱 0918023813 | F29: ='人員資料表'!G18 -> D/大眾化白雪村採樟腦 | H29: ='人員資料表'!M18&CHAR(10)&TEXT('人員資料表'!N18,"yyyy/mm/dd") -> S225265256 2005/10/17 | K29: ='人員資料表'!P18&CHAR(10)&'人員資料表'!Q18 -> 黃范竹芳（母女） 0976525634 | M29: ='人員資料表'!S18 -> 不知道⋯ | N29: ='人員資料表'!T18 -> 無
B30: ='人員資料表'!K19&CHAR(10)&'人員資料表'!L19 -> 機械118 E14146252 | D30: ='人員資料表'!E19&CHAR(10)&'人員資料表'!J19 -> 傅琨鋮 0968716529 | F30: ='人員資料表'!G19 -> D/馬海濮大眾化 | H30: ='人員資料表'!M19&CHAR(10)&TEXT('人員資料表'!N19,"yyyy/mm/dd") -> E126264303 2007/03/15 | K30: ='人員資料表'!P19&CHAR(10)&'人員資料表'!Q19 -> 張嘉玲（母子） 0939042620 | M30: ='人員資料表'!S19 -> B | N30: ='人員資料表'!T19 -> 無
B31: ='人員資料表'!K20&CHAR(10)&'人員資料表'!L20 -> 電機116 E24121026 | D31: ='人員資料表'!E20&CHAR(10)&'人員資料表'!J20 -> 吳琇如 0983509656 | F31: ='人員資料表'!G20 -> C/萬山岩雕 | H31: ='人員資料表'!M20&CHAR(10)&TEXT('人員資料表'!N20,"yyyy/mm/dd") -> A231279243 2004/09/09 | K31: ='人員資料表'!P20&CHAR(10)&'人員資料表'!Q20 -> 黃燕嬌（母女） 0939065504 | M31: ='人員資料表'!S20 -> O | N31: ='人員資料表'!T20 -> 伊普芬
B32: ='人員資料表'!K21&CHAR(10)&'人員資料表'!L21 -> 電機116 E24124236 | D32: ='人員資料表'!E21&CHAR(10)&'人員資料表'!J21 -> 邱于馨 0905274951 | F32: ='人員資料表'!G21 -> X | H32: ='人員資料表'!M21&CHAR(10)&TEXT('人員資料表'!N21,"yyyy/mm/dd") -> E225614669 2005/06/01 | K32: ='人員資料表'!P21&CHAR(10)&'人員資料表'!Q21 -> 邱逸民（父女） 0933003294 | M32: ='人員資料表'!S21 -> O | N32: ='人員資料表'!T21 -> 無
B33: ='人員資料表'!K23&CHAR(10)&'人員資料表'!L23 | D33: ='人員資料表'!E23&CHAR(10)&'人員資料表'!J23 | M33: ='人員資料表'!S23 | N33: ='人員資料表'!T23
B34: ='人員資料表'!K24&CHAR(10)&'人員資料表'!L24 | D34: ='人員資料表'!E24&CHAR(10)&'人員資料表'!J24 | M34: ='人員資料表'!S24 | N34: ='人員資料表'!T24
B35: ='人員資料表'!K25&CHAR(10)&'人員資料表'!L25 | D35: ='人員資料表'!E25&CHAR(10)&'人員資料表'!J25 | M35: ='人員資料表'!S25 | N35: ='人員資料表'!T25
B36: ='人員資料表'!K26&CHAR(10)&'人員資料表'!L26 | D36: ='人員資料表'!E26&CHAR(10)&'人員資料表'!J26 | M36: ='人員資料表'!S26 | N36: ='人員資料表'!T26
B37: ='人員資料表'!K27&CHAR(10)&'人員資料表'!L27 | D37: ='人員資料表'!E27&CHAR(10)&'人員資料表'!J27 | M37: ='人員資料表'!S27 | N37: ='人員資料表'!T27
B38: ='人員資料表'!K28&CHAR(10)&'人員資料表'!L28 | D38: ='人員資料表'!E28&CHAR(10)&'人員資料表'!J28 | M38: ='人員資料表'!S28 | N38: ='人員資料表'!T28
B39: ='人員資料表'!K29&CHAR(10)&'人員資料表'!L29 | D39: ='人員資料表'!E29&CHAR(10)&'人員資料表'!J29 | M39: ='人員資料表'!S29 | N39: ='人員資料表'!T29
B40: ='人員資料表'!K30&CHAR(10)&'人員資料表'!L30 | D40: ='人員資料表'!E30&CHAR(10)&'人員資料表'!J30 | M40: ='人員資料表'!S30 | N40: ='人員資料表'!T30

Sheet 人員資料表
A3: 範例
A4: 填寫時間 | B4: 蒐集資料同意 | C4: 想說的話 | E4: 全名 | F4: 嚮導隊 | G4: 資歷 | H4: 生理性別 | I4: 臉書網址 FB | J4: 手機 | K4: 系級 | L4: 學號 | M4: 身分證字號 | N4: 生日 | O4: 戶籍地址 | P4: 緊急聯絡人 | Q4: 緊急連絡人電話 | R4: 保險受益人 | S4: 血型 | T4: 藥物過敏史 | U4: CPR急救認證 | V4: 急救認證期限 | W4: 討厭吃 | X4: 電子郵件 | Z4: 先天/遺傳/慢性性病史 | AE4: 一 | AF4: 二 | AG4: 三 | AH4: 四 | AI4: 五
A5: 44986.837 | B5: 資深繳費會員，願意成為每次出隊資料使用 【歡迎隨時登入更新資料】 | C5: X | E5: 程效賢 | F5: 熊 | G5: A/奇萊東稜下嵐山 | H5: 男 BOY | I5: 程效賢 | J5: 0939952841 | K5: 土木114 | L5: E64102038 | M5: F131195218 | N5: 37516 | O5: 新北市永和區博愛街19巷7號2樓 | P5: 金愛君（母子） | Q5: 0952952841 | R5: 同 緊急聯絡人 ENMERGENCY CONTECT PERSON | S5: B | T5: NKDA | W5: 榴槤 納豆 芋頭 | X5: E64102038@gs.ncku.edu.tw | Z5: 無 | AD5: o
A6: 45360.049 | B6: 資深繳費會員，願意成為每次出隊資料使用 【歡迎隨時登入更新資料】 | C6: 博博白雪大眾化 | E6: 宋侑達 | F6: 羊 | G6: B活/大壩聖稜 | H6: 男 BOY | I6: https://www.facebook.com/profile.php?id=100011330507694 | J6: 0966139234 | K6: 水利114 | L6: E84104034 | M6: L125840395 | N6: 37591 | O6: 台中市豐原區鐮村路465巷64弄16號 | P6: 宋坤龍（父子） | Q6: 0928542036 | R6: 同 緊急聯絡人 ENMERGENCY CONTECT PERSON | S6: A | T6: NKDA | W6: 無 | X6: leo66pig@gmail.com | Z6: 無 | AA6: 50034 | AB6: 45359
A7: 45887.613 | B7: 資深繳費會員，願意成為每次出隊資料使用 【歡迎隨時登入更新資料】 | C7: 呵呵呵呵 | E7: 陳柏亨 | F7: 狼 | G7: 12A 童話嘆息 | H7: 男 BOY | I7: 陳柏亨 | J7: 0905377012 | K7: 地科114 | L7: C44106206 | M7: E125475393 | N7: 37770 | O7: 高雄市苓雅區中正二路103號八樓之一 | P7: 張文瀞（母子） | Q7: 0929331445 | R7: 同 緊急聯絡人 ENMERGENCY CONTECT PERSON | S7: B | T7: 無 | W7: 香菜香菜香菜 | X7: chenhenry2003@gmail.com | Z7: 無 | AD7: 2D溯 爺巴堪
A8: 44880.042 | B8: 資深繳費會員，願意成為每次出隊資料使用 【歡迎隨時登入更新資料】 | C8: X | E8: 張薰慈 | F8: 三 | G8: A/知本林鐵 | H8: 女 GIRL | I8: 張薰慈 | J8: 0976818408 | K8: 牙醫115 | L8: I94096024 | M8: F230782791 | N8: 37184 | O8: 新北市土城區承天路107巷14號三樓 | P8: 徐碧卿（母女） | Q8: 0976533082 | R8: 同 緊急聯絡人 ENMERGENCY CONTECT PERSON | S8: O | T8: 無 | W8: 甲殼類海鮮過敏（蝦子、螃蟹） | X8: I94096024@gs.ncku.edu.tw | Z8: 無 | AA8: 已經現繳給總務（？）了
A9: 45918.636 | B9: 資深繳費會員，同意作為社團通訊錄使用 (僅公開：姓名、系級、嚮導隊、電話) | C9: 扁桃腺 | E9: 陳莉臻 | F9: 鷹 | G9: B/剩餞 | H9: 女 GIRL | I9: 陳莉臻 | J9: 0905574912 | K9: 資訊115 | L9: AN4116063 | M9: O200644071 | N9: 38044 | O9: 新竹市北區西大路681巷12號 | P9: 張雅惠（母女） | Q9: 0922313887 | R9: 同 緊急聯絡人 ENMERGENCY CONTECT PERSON | S9: AB | T9: NKDA | W9: 午餐肉 | X9: lileee0801@gmail.com | AD9: 2D/初溯
A10: 45742.891 | B10: 資深繳費會員，願意成為每次出隊資料使用 【歡迎隨時登入更新資料】 | C10: × | E10: 張仁熏 | F10: 狼 | G10: A/知本林鐵 | H10: 男 BOY | I10: https://www.facebook.com/share/KD6oNSX6DdMYHvW4/ | J10: 0912683511 | K10: 心理117 | L10: D84136014 | M10: A132077143 | N10: 38845 | O10: 台北市大同區敦煌路80巷2號9樓之二 | P10: 蔡茵如（母子） | Q10: 0921308802 | R10: 同 緊急聯絡人 ENMERGENCY CONTECT PERSON | S10: O | T10: 無 | W10: 香菜 | X10: d84136014@gs.ncku.edu.tw | Z10: 無 | AA10: 69504 | AB10: 45569
A11: 46093.706 | B11: 【剛剛繳完會費了!】 | C11: 羅娜神木隊大眾化 | E11: 曾翔鈺 | F11: 隊 | G11: 8B/丹大溫泉 | H11: 女 GIRL | I11: Shiang Yu Tseng | J11: 0926801336 | K11: 生科碩二 | L11: L56134166 | M11: A230567431 | N11: 37071 | O11: 臺北市文山區興隆路二段203巷80號9樓 | P11: 曾厚勳（父女） | Q11: 0927238063 | R11: 同 緊急聯絡人 SAME AS EMERGENCY CONTACT PERSON | S11: B | T11: NKDA | W11: 豆製品 | X11: mable.tseng@gmail.com | AA11: 現金 | AB11: 45721 | AD11: D/鮭魚炒飯
A12: 45360.446 | B12: 資深繳費會員，願意成為每次出隊資料使用 【歡迎隨時登入更新資料】 | C12: 白雪村大眾化 | E12: 李思誼 | F12: 星 | G12: 8B勘/巴冷公主撞月樹 | H12: 女 GIRL | I12: https://www.facebook.com/profile.php?id=100002945606561 | J12: 0985204657 | K12: 建研所 | L12: E74096035 | M12: F230379909 | N12: 37214 | O12: 新北市板橋區長江路二段93號3樓 | P12: 李昭俊（父女） | Q12: 0922023106 | R12: 同 緊急聯絡人 ENMERGENCY CONTECT PERSON | S12: O | T12: NKDA | W12: nope | X12: sunny12345330@gmail.com | Z12: nope
A13: 45837.937 | B13: 資深繳費會員，願意成為每次出隊資料使用 【歡迎隨時登入更新資料】 | C13: 白雪村大眾化 | E13: 楊育銘 | F13: 狼 | G13: C活/西拉歐卡 | H13: 男 BOY | I13: https://www.facebook.com/profile.php?id=100006236040371 | J13: 0986873262 | K13: 資源所112 | L13: N46114213 | M13: A127342866 | N13: 36392 | O13: 高雄市三民區松江街22號 | P13: 楊定恭（父子） | Q13: 0963278285 | R13: 同 緊急聯絡人 ENMERGENCY CONTECT PERSON | S13: O | T13: NKDA | W13: 茄子 | X13: ga2877536@gmail.com | Z13: 無 | AA13: 50034 | AB13: 36392 | AD13: 初溯
A14: 45921.539 | B14: 【剛剛繳完會費了!】 | C14: X | E14: 邱以昕 | F14: 新生 freshman | G14: C/忘了 | H14: 男 BOY | I14: https://www.facebook.com/share/1E5diB4wxx/?mibextid=wwXIfr | J14: 0978001281 | K14: 土木118 | L14: E64141090 | M14: A132065296 | N14: 39292 | O14: 台北市士林區忠誠路一段112號5樓 | P14: 邱威凱（父子） | Q14: 0972811139 | R14: 同 緊急聯絡人 SAME AS EMERGENCY CONTACT PERSON | S14: O | T14: NKDA | W14: 一切蕈類 | X14: Sha948887@gmail.com | Z14: 無 | AA14: 2603 | AB14: 45921 | AD14: X上溯/外雙溪 | AE14: o | AG14: o | AH14: o
A15: 46094.446 | B15: 【剛剛繳完會費了!】 | C15: 哆啦a夢大雄的鋼鐵兵團 | E15: 劉祐任 | F15: 新生 freshman | G15: D/大眾化白雪村採樟腦 | H15: 男 BOY | I15: 劉祐任 | J15: 0934212106 | K15: 航太118 | L15: F44141151 | M15: N126883789 | N15: 38768 | O15: 彰化縣二林鎮西平里中正路65號 | P15: 劉玠庭（父子） | Q15: 0953080665 | R15: 同 緊急聯絡人 SAME AS EMERGENCY CONTACT PERSON | S15: O | T15: 無NKDA | W15: 無 | X15: youren0220@gmail.com | AA15: 已現金繳費 | AB15: 46093 | AD15: X | AH15: o
A16: 46092.628 | B16: 資深繳費會員，願意成為每次出隊資料使用 【歡迎隨時登入更新資料】 | C16: 馬海僕大眾化，［抱大腿🫂🦵］偉大的大大學長姐們，我是個菜菜，求學長姊撈撈，菜菜，撈撈Orz | E16: 郭佳宛 | F16: 新生 freshman | G16: C/萬山岩雕 | H16: 女 GIRL | I16: https://www.facebook.com/crazie.kuo | J16: 0906871119 | K16: 台文118 | L16: B54144726 | M16: N226495432 | N16: 39030 | O16: 彰化縣鹿港鎮鹿東里2鄰鹿東路244號 | P16: 劉婉慧（母女） | Q16: 0918879151 | R16: 同 緊急聯絡人 SAME AS EMERGENCY CONTACT PERSON | S16: A | T16: NKDA | W16: 各種肉、海鮮、茄子、秋葵、桂圓、芝麻、韭菜、青椒、洋蔥、牛奶被單獨出現、胡蘿蔔、苦瓜、芹菜、蔥薑蒜、香菜、紅棗 | X16: crazie1109@gmail.com | Z16: 無 | AA16: 於社辦繳交 | AB16: 45922 | AD16: X | AE16: o
A17: 45930.86 | B17: 【剛剛繳完會費了!】 | C17: X | E17: 蔡岳承 | F17: 新生 freshman | G17: D勘/蛟龍爬去哪 | H17: 男 BOY | I17: https://www.facebook.com/share/1Cj373UwWa/ | J17: 0909323691 | K17: 生科碩一 | L17: L56144137 | M17: B123726590 | N17: 37403 | O17: 臺中市南屯區向心里1鄰南屯路二段269號 | P17: 蔡至強（父子） | Q17: 0923309046 | R17: 同 緊急聯絡人 SAME AS EMERGENCY CONTACT PERSON | S17: O | T17: 無 | W17: 無 | X17: voyagueyct@gmail.com | Z17: 高山反應 | AA17: 給劉 | AB17: 45930 | AD17: X | AE17: o | AH17: o | AI17: o
A18: 45722.38 | B18: 【剛剛繳完會費了!】 | C18: 水漾羅娜神木大眾化 | E18: 張婷萱 | F18: 新生 | G18: D/大眾化白雪村採樟腦 | H18: 女 GIRL | I18: https://www.facebook.com/share/18FcvE3SrM/?mibextid=wwXIfr | J18: 0918023813 | K18: 心理117 | L18: D84134020 | M18: S225265256 | N18: 38642 | O18: 高雄市桃源區勤和里南橫公路三段33號 | P18: 黃范竹芳（母女） | Q18: 0976525634 | R18: 同 緊急聯絡人 ENMERGENCY CONTECT PERSON | S18: 不知道⋯ | T18: 無 | W18: 不吃辣，其他都吃！ | X18: zhangtingxuan017@gmail.com | Z18: 無 | AA18: 45198 | AB18: 45722 | AE18: o | AH18: o | AI18: o
A19: 45929.954 | B19: 【剛剛繳完會費了!】 | C19: 馬海濮大眾化 | E19: 傅琨鋮 | F19: 新生 freshman | G19: D/馬海濮大眾化 | H19: 男 BOY | I19: 傅琨鋮 | J19: 0968716529 | K19: 機械118 | L19: E14146252 | M19: E126264303 | N19: 39156 | O19: 新竹縣竹北市復興三路二段106號十樓 | P19: 張嘉玲（母子） | Q19: 0939042620 | R19: 同 緊急聯絡人 SAME AS EMERGENCY CONTACT PERSON | S19: B | T19: 無 | W19: 無 | X19: kunchengfu24@gmail.com | Z19: 無 | AA19: 現金 | AB19: 45930 | AD19: X | AE19: o | AG19: o
A20: 45839.002 | B20: 非會員，僅作為單次活動使用 (每次出隊費 $50) | C20: 淡蘭南路 | E20: 吳琇如 | F20: 新生 | G20: C/萬山岩雕 | H20: 女 GIRL | I20: https://www.facebook.com/share/19UEh2BWiS/?mibextid=wwXIfr | J20: 0983509656 | K20: 電機116 | L20: E24121026 | M20: A231279243 | N20: 38239 | O20: 台北市北投區志遠三路45號三樓 | P20: 黃燕嬌（母女） | Q20: 0939065504 | R20: 同 緊急聯絡人 ENMERGENCY CONTECT PERSON | S20: O | T20: 伊普芬 | U20: https://drive.google.com/open?id=1eEiH7y3l-Zxah1wdM7i5dl8CHxrgmhPG, https://drive.google.com/open?id=1ovJSIgrqfaZZhlwR2NKDWHZ--qtZwPgs, https://drive.google.com/open?id=1fbirEdy3YsdZDEnPUsuVWvETrHNwErsV | W20: 基本上都還是會吃啦 但不喜歡茄子苦瓜內臟 | X20: E24121026@gs.ncku.edu.tw | Z20: 沒吧 | AA20: 28991 | AD20: X | AI20: o
A21: 46085.826 | B21: 【剛剛繳完會費了!】 | C21: X | E21: 邱于馨 | F21: 新生 freshman | G21: X | H21: 女 GIRL | I21: 邱于馨 | J21: 0905274951 | K21: 電機116 | L21: E24124236 | M21: E225614669 | N21: 38504 | O21: 高雄市三民區河北一路48號 | P21: 邱逸民（父女） | Q21: 0933003294 | R21: 同 緊急聯絡人 SAME AS EMERGENCY CONTACT PERSON | S21: O | T21: 無 | W21: 玉米（但多力多滋🉑）、芋頭、米血 | X21: Mina940601@gmail.com | Z21: 無 | AA21: 04248 | AB21: 46085 | AD21: X

Sheet 紀錄與估時行程時間軸照片
B1: 20:00 更新山下資訊 | D1: D1 | E1: D2 | F1: D3 | G1: 紀錄
B2: 19:00 回報山上決策 | D2: 46143 | E2: 46144 | F2: 46145
B3: 預期營地 | D3: 寬稜 營地 | E3: 河灘 營地 | G3: https://www.keepon.com.tw/thread-7b47a509-10d8-e411-93ec-000e04b74954.html
B4: 預期訊號點 | D4: X | E4: X | F4: X
A5: 麻煩留守的事情 完成請打勾 | G5: https://www.keepon.com.tw/thread-9078f29d-15d8-e411-93ec-000e04b74954.html
A6: [傳訊]
A7: inreach點位連結(家人) | B7: https://share.garmin.com/sttsgarmin | G7: https://tcmb.culture.tw/zh-tw/detail?indexCode=Culture_Object&id=270813
A8: inreach管理業面(留守) (帳密在雲端) | B8: https://explore.garmin.com/ | C8: 接收 | D8: FALSE | E8: TRUE | G8: https://dl.lib.ntu.edu.tw/s/forest/item/94488#?c=&m=&s=&cv=
C9: 傳出 | D9: FALSE | E9: FALSE
A10: [天氣]
A11: CWB 看紫外線&下雨時段和氣候類型&天氣概況&氣溫&風向
A12: CWB 屏東縣獅子鄉 | B12: https://www.cwa.gov.tw/V8/C/W/Town/Town.html?TID=1001332 | D12: FALSE | E12: FALSE
A13: CWB 台東縣達仁鄉 | B13: https://www.cwa.gov.tw/V8/C/W/Town/Town.html?TID=1001415 | D13: FALSE | E13: FALSE
A14: CWB 定量水預報 (現在預報2天12hr*4) | B14: https://www.cwa.gov.tw/V8/C/P/QPF.html | D14: FALSE | E14: FALSE
A15: CWB 天氣概況 | B15: https://www.cwa.gov.tw/V8/C/W/index.html | D15: FALSE | E15: FALSE
A16: WINDY 看雲底高度和風向
A17: 茶茶牙頓山 | B17: https://www.windy.com/22.347/120.768?22.352,120.796,13 | D17: FALSE | E17: FALSE
B18: https://www.ventusky.com/zh-tw/22.347;120.768 | D18: FALSE | E18: FALSE
A20: [路況] 浸水營東西段、西都驕溪登山口路況 | D20: FALSE | E20: FALSE | G20: [水] 茶茶牙頓溪/新都驕溪/西都驕溪/石壁穩定活水
A21: [水況] 西都驕溪、新都驕溪、大武溪新水況 | D21: FALSE | E21: FALSE
A22: [颱風] 無 | D22: FALSE | E22: FALSE
A23: FB 林道路況分享 | B23: https://www.facebook.com/groups/138744813447101 | G23: [訊] 無相關資料
A24: FB 登山借問站 | B24: https://www.facebook.com/groups/1653614654914504
A25: 備註資料
A26: 集水區觀察員/大漢山測站
A27: https://wiwari.github.io/accTW/?
A28: https://codis.cwa.gov.tw/StationData
A29: 中央氣象局 天氣預報圖
A30: https://www.cwa.gov.tw/V8/C/W/analysis.html
A31: 國土測繪圖資服務網(112年空載光達+1/5000基本地形圖109年+魯地圖)
A32: https://maps.nlsc.gov.tw/T09/mapshow.action?In_type=web#
A36: 估時 | G36: 7人 | H36: 16人 | I36: 8人 | J36: Unknown | K36: 7人 | L36: Unknown
A37: 正式路線 | C37: 估時 | G37: 2023/01/07 一七去茶茶 | H37: 2021/12/31 路程遙遠的茶茶牙頓山 | I37: 2020/12/25 二勘茶茶牙頓 | J37: 2022/2/26 茶茶牙頓山 | K37: 2022/12/31 內麻里巴加芝來 | L37: 2017/11/30 茶茶牙頓大武未竟路線 | M37: 估時
G38: 相簿
A39: D1 5/1 (0519日出 1823日落)
A40: 成大光口 | C40: 0230 | M40: 2000
C41: 210m(Google Map 170m) | M41: 210m(Google Map 170m)
A42: 姑仔崙吊橋 C0 | C42: 0600 | G42: 1525 | I42: 1458 | L42: 1337 | M42: 0600
C43: 150m | G43: ⭡ | I43: ⭡ | M43: 150m
A44: 大武溪溪底登山口H200 | C44: 0830 | G44: 1240/1325 | I44: 1308/1349 | L44: 1428/0602 | M44: 0830
...

Sheet 入山申請文件
A1: 填寫說明： 1.必輸入欄位:姓名、性別、出生年別、出生日期、國別、身分證號/護照號碼、電話、地址、緊急聯絡人姓名、緊急聯絡電話。 2.性別：請輸入代號如 1:男 2:女。 3.出生年別：請輸入代號如 1:民國 2:西元。 4.出生日期：請依出生年別輸入。出生年別為1民國：格式為YYYMMDD，如：0901010。出生年別為2西元：格式為YYYYMMDD，如20011010。 5.國別：請輸入代號如 1：國人 2：外國人。 6.黃色區塊(填寫說明及標題列)不可刪除及異動！資料必須從空白處開始填寫。
A2: 姓名 | B2: 性別 | C2: 出生年別 | D2: 出生日期 | E2: 國別 | F2: 身分證字號/ 護照號碼 | G2: 電話 | H2: 電子郵件 | I2: 地址 | J2: 緊急聯絡人姓名 | K2: 緊急聯絡電話 | L2: 備註
A3: 張三 | B3: 2 | C3: 1 | D3: 901010 | E3: 1 | F3: A223456789 | G3: 02-23931791 | H3: sample@yahoo.com.tw | I3: 台北市中正區忠孝東路一段7號 | J3: 李四 | K3: 02-23931792 | L3: 範例
A4: ='人員資料表'!E5 -> 程效賢 | B4: =if('人員資料表'!H5="女 GIRL",2,1) -> 1 | C4: 2 | D4: =TEXT('人員資料表'!N5,"yyyymmdd") -> 20020917 | E4: =if(LEN('人員資料表'!M5)=10,1,2) -> 1 | F4: ='人員資料表'!M5 -> F131195218 | G4: ='人員資料表'!J5 -> 0939952841 | H4: ='人員資料表'!X5 -> E64102038@gs.ncku.edu.tw | I4: ='人員資料表'!O5 -> 新北市永和區博愛街19巷7號2樓 | J4: =Left('人員資料表'!P5,Search("（",'人員資料表'!P5,1)-1) -> 金愛君 | K4: ='人員資料表'!Q5 -> 0952952841
A5: ='人員資料表'!E6 -> 宋侑達 | B5: =if('人員資料表'!H6="女 GIRL",2,1) -> 1 | C5: 2 | D5: =TEXT('人員資料表'!N6,"yyyymmdd") -> 20021201 | E5: =if(LEN('人員資料表'!M6)=10,1,2) -> 1 | F5: ='人員資料表'!M6 -> L125840395 | G5: ='人員資料表'!J6 -> 0966139234 | H5: ='人員資料表'!X6 -> leo66pig@gmail.com | I5: ='人員資料表'!O6 -> 台中市豐原區鐮村路465巷64弄16號 | J5: =Left('人員資料表'!P6,Search("（",'人員資料表'!P6,1)-1) -> 宋坤龍 | K5: ='人員資料表'!Q6 -> 0928542036
A6: ='人員資料表'!E7 -> 陳柏亨 | B6: =if('人員資料表'!H7="女 GIRL",2,1) -> 1 | C6: 2 | D6: =TEXT('人員資料表'!N7,"yyyymmdd") -> 20030529 | E6: =if(LEN('人員資料表'!M7)=10,1,2) -> 1 | F6: ='人員資料表'!M7 -> E125475393 | G6: ='人員資料表'!J7 -> 0905377012 | H6: ='人員資料表'!X7 -> chenhenry2003@gmail.com | I6: ='人員資料表'!O7 -> 高雄市苓雅區中正二路103號八樓之一 | J6: =Left('人員資料表'!P7,Search("（",'人員資料表'!P7,1)-1) -> 張文瀞 | K6: ='人員資料表'!Q7 -> 0929331445
A7: ='人員資料表'!E8 -> 張薰慈 | B7: =if('人員資料表'!H8="女 GIRL",2,1) -> 2 | C7: 2 | D7: =TEXT('人員資料表'!N8,"yyyymmdd") -> 20011020 | E7: =if(LEN('人員資料表'!M8)=10,1,2) -> 1 | F7: ='人員資料表'!M8 -> F230782791 | G7: ='人員資料表'!J8 -> 0976818408 | H7: ='人員資料表'!X8 -> I94096024@gs.ncku.edu.tw | I7: ='人員資料表'!O8 -> 新北市土城區承天路107巷14號三樓 | J7: =Left('人員資料表'!P8,Search("（",'人員資料表'!P8,1)-1) -> 徐碧卿 | K7: ='人員資料表'!Q8 -> 0976533082
A8: ='人員資料表'!E9 -> 陳莉臻 | B8: =if('人員資料表'!H9="女 GIRL",2,1) -> 2 | C8: 2 | D8: =TEXT('人員資料表'!N9,"yyyymmdd") -> 20040227 | E8: =if(LEN('人員資料表'!M9)=10,1,2) -> 1 | F8: ='人員資料表'!M9 -> O200644071 | G8: ='人員資料表'!J9 -> 0905574912 | H8: ='人員資料表'!X9 -> lileee0801@gmail.com | I8: ='人員資料表'!O9 -> 新竹市北區西大路681巷12號 | J8: =Left('人員資料表'!P9,Search("（",'人員資料表'!P9,1)-1) -> 張雅惠 | K8: ='人員資料表'!Q9 -> 0922313887
A9: ='人員資料表'!E10 -> 張仁熏 | B9: =if('人員資料表'!H10="女 GIRL",2,1) -> 1 | C9: 2 | D9: =TEXT('人員資料表'!N10,"yyyymmdd") -> 20060508 | E9: =if(LEN('人員資料表'!M10)=10,1,2) -> 1 | F9: ='人員資料表'!M10 -> A132077143 | G9: ='人員資料表'!J10 -> 0912683511 | H9: ='人員資料表'!X10 -> d84136014@gs.ncku.edu.tw | I9: ='人員資料表'!O10 -> 台北市大同區敦煌路80巷2號9樓之二 | J9: =Left('人員資料表'!P10,Search("（",'人員資料表'!P10,1)-1) -> 蔡茵如 | K9: ='人員資料表'!Q10 -> 0921308802
A10: ='人員資料表'!E11 -> 曾翔鈺 | B10: =if('人員資料表'!H11="女 GIRL",2,1) -> 2 | C10: 2 | D10: =TEXT('人員資料表'!N11,"yyyymmdd") -> 20010629 | E10: =if(LEN('人員資料表'!M11)=10,1,2) -> 1 | F10: ='人員資料表'!M11 -> A230567431 | G10: ='人員資料表'!J11 -> 0926801336 | H10: ='人員資料表'!X11 -> mable.tseng@gmail.com | I10: ='人員資料表'!O11 -> 臺北市文山區興隆路二段203巷80號9樓 | J10: =Left('人員資料表'!P11,Search("（",'人員資料表'!P11,1)-1) -> 曾厚勳 | K10: ='人員資料表'!Q11 -> 0927238063
A11: ='人員資料表'!E12 -> 李思誼 | B11: =if('人員資料表'!H12="女 GIRL",2,1) -> 2 | C11: 2 | D11: =TEXT('人員資料表'!N12,"yyyymmdd") -> 20011119 | E11: =if(LEN('人員資料表'!M12)=10,1,2) -> 1 | F11: ='人員資料表'!M12 -> F230379909 | G11: ='人員資料表'!J12 -> 0985204657 | H11: ='人員資料表'!X12 -> sunny12345330@gmail.com | I11: ='人員資料表'!O12 -> 新北市板橋區長江路二段93號3樓 | J11: =Left('人員資料表'!P12,Search("（",'人員資料表'!P12,1)-1) -> 李昭俊 | K11: ='人員資料表'!Q12 -> 0922023106
A12: ='人員資料表'!E13 -> 楊育銘 | B12: =if('人員資料表'!H13="女 GIRL",2,1) -> 1 | C12: 2 | D12: =TEXT('人員資料表'!N13,"yyyymmdd") -> 19990820 | E12: =if(LEN('人員資料表'!M13)=10,1,2) -> 1 | F12: ='人員資料表'!M13 -> A127342866 | G12: ='人員資料表'!J13 -> 0986873262 | H12: ='人員資料表'!X13 -> ga2877536@gmail.com | I12: ='人員資料表'!O13 -> 高雄市三民區松江街22號 | J12: =Left('人員資料表'!P13,Search("（",'人員資料表'!P13,1)-1) -> 楊定恭 | K12: ='人員資料表'!Q13 -> 0963278285
A13: ='人員資料表'!E14 -> 邱以昕 | B13: =if('人員資料表'!H14="女 GIRL",2,1) -> 1 | C13: 2 | D13: =TEXT('人員資料表'!N14,"yyyymmdd") -> 20070729 | E13: =if(LEN('人員資料表'!M14)=10,1,2) -> 1 | F13: ='人員資料表'!M14 -> A132065296 | G13: ='人員資料表'!J14 -> 0978001281 | H13: ='人員資料表'!X14 -> Sha948887@gmail.com | I13: ='人員資料表'!O14 -> 台北市士林區忠誠路一段112號5樓 | J13: =Left('人員資料表'!P14,Search("（",'人員資料表'!P14,1)-1) -> 邱威凱 | K13: ='人員資料表'!Q14 -> 0972811139
A14: ='人員資料表'!E15 -> 劉祐任 | B14: =if('人員資料表'!H15="女 GIRL",2,1) -> 1 | C14: 2 | D14: =TEXT('人員資料表'!N15,"yyyymmdd") -> 20060220 | E14: =if(LEN('人員資料表'!M15)=10,1,2) -> 1 | F14: ='人員資料表'!M15 -> N126883789 | G14: ='人員資料表'!J15 -> 0934212106 | H14: ='人員資料表'!X15 -> youren0220@gmail.com | I14: ='人員資料表'!O15 -> 彰化縣二林鎮西平里中正路65號 | J14: =Left('人員資料表'!P15,Search("（",'人員資料表'!P15,1)-1) -> 劉玠庭 | K14: ='人員資料表'!Q15 -> 0953080665
A15: ='人員資料表'!E16 -> 郭佳宛 | B15: =if('人員資料表'!H16="女 GIRL",2,1) -> 2 | C15: 2 | D15: =TEXT('人員資料表'!N16,"yyyymmdd") -> 20061109 | E15: =if(LEN('人員資料表'!M16)=10,1,2) -> 1 | F15: ='人員資料表'!M16 -> N226495432 | G15: ='人員資料表'!J16 -> 0906871119 | H15: ='人員資料表'!X16 -> crazie1109@gmail.com | I15: ='人員資料表'!O16 -> 彰化縣鹿港鎮鹿東里2鄰鹿東路244號 | J15: =Left('人員資料表'!P16,Search("（",'人員資料表'!P16,1)-1) -> 劉婉慧 | K15: ='人員資料表'!Q16 -> 0918879151
... A20: ='人員資料表'!E21 -> 邱于馨 | B20: =if('人員資料表'!H21="女 GIRL",2,1) -> 2 | C20: 2 | D20: =TEXT('人員資料表'!N21,"yyyymmdd") -> 20050601 | E20: =if(LEN('人員資料表'!M21)=10,1,2) -> 1 | F20: ='人員資料表'!M21 -> E225614669 | G20: ='人員資料表'!J21 -> 0905274951 | H20: ='人員資料表'!X21 -> Mina940601@gmail.com | I20: ='人員資料表'!O21 -> 高雄市三民區河北一路48號 | J20: =Left('人員資料表'!P21,Search("（",'人員資料表'!P21,1)-1) -> 邱逸民 | K20: ='人員資料表'!Q21 -> 0933003294
A29: ='人員資料表'!E34

Sheet 藥單
B2: 成大山協：醫藥箱借用單 | F2: 請下載填寫！！！ | J2: 20250306更新
B3: 隊伍名稱 | C3: 茶茶牙頓出西都驕溪 | F3: 日期 | G3: 2026/05/01-05/03 | J3: 天數 | K3: 3
B4: 級數 / 性質(活、勘) | C4: D | D4: 勘 | E4: =IF(G4>G5,"O","X") -> O | F4: 最高海拔 | G4: 1325 | I4: m | J4: 人數 | K4: 17
B5: 過敏病史 (人/藥物) | C5: 伊普芬 | J5: 開藥負責人 | K5: 效賢
E6: =IF(G4>G6,1,0) -> 0 | G6: 2600 | H6: =IF(G4>G6,1) -> FALSE
B7: 內用藥 | C7: 每顆劑量 | D7: 用法 | F7: 數量 | G7: 用品/工具 | I7: 數量 | J7: [需求顆數參考公式] 公式僅供參考，依隊伍人員性質決定常用藥 ▍常用藥(消炎、止痛)： 1/4人數*1/2天數*顆/天 ▍非常用藥： 1/8人數*1/2天數*顆/天 ▍藥物過敏： *為蠶豆症禁用或有疑慮的藥物，請謹慎使用 ¶為磺胺類藥物過敏者禁用或有疑慮的藥物，請謹慎使用 免責聲明：以上標記僅供參考，無標示的藥物不代表不會發生藥物過敏，曾有藥物過敏史的患者請洽尋醫師或攜帶個人醫藥包 [借用規範] • 借用單命名方式： 隊伍名稱_日期_人數_借用者 • 出隊前的一週前提出申請 • 下山後一週內歸還醫藥箱 [租借費用] ▍社內隊 A級：50 / 人 B級：30 / 人 C,D：不收費 ▍社外隊 A：100 / 人 B,C,D：50 / 人 [諮詢電話] +1-720-485-1393 Dr.王士豪 衛星電話可直撥，手機請加002或009直撥
B8: Acetaminophen (止痛劑) | C8: 500mg | D8: 每4~6小時1顆(500mg/6hr) | E8: =(($K$3/2)*$K$4)/4*4 -> 25.5 | F8: 16 | G8: 2*2紗布 /包 | H8: =K3*K4/8 -> 6.375 | I8: 6
B9: Celecoxib*¶ (消炎劑) | C9: 200mg | D9: 第一次2顆，可追加一顆；第二天開始每12小時1顆(200mg/12hr) | E9: =($K$3*$K$4/2)/4*3 -> 19.125 | F9: 24 | G9: 4*4紗布 /包 | H9: =K3*K4/8 -> 6.375 | I9: 4
B10: Loperamide (止瀉劑) | C10: 2mg | D10: 第一次2顆(4mg)，之後每次腹瀉後追加1顆(2mg) | E10: =($K$3/2*$K$4)/8*2 -> 6.375 | F10: 16 | G10: 彈性繃帶 /捲 | H10: =(K3/2)*K4/4 -> 6.375 | I10: 2
B11: Famotidine FC (制酸劑) | C11: 20mg | D11: 每12小時1顆(20mg/12hr) | E11: =($K$3/2*$K$4)/8*3 -> 9.5625 | F11: 16 | G11: OK繃大 /片 | H11: =(K3/3)*K4 -> 17 | I11: 8
B12: Loratadine (抗組織胺) | C12: 10mg | D12: 每天1顆(10mg/24hr) | E12: =($K$3*$K$4)/4*1 -> 12.75 | F12: 20 | G12: OK繃小 /片 | H12: =H10/2 -> 3.1875 | I12: 12
B13: Augmentin (抗生素) | C13: 1000mg | D13: 每12小時1顆(1000mg/12hr) | E13: =($K$3/2*$K$4)/4*2 -> 12.75 | F13: 12 | G13: 防水OK繃大 /片 | H13: =H11/3 -> 5.6666667 | I13: 8
B14: Acetazolamide*¶ (丹木斯) | C14: 250mg | D14: (預防125mg/12hr。) 每12小時1~2顆(250~500mg/12hr) | E14: =($K$3*$K$4)*E6 -> 0 | F14: 0 | G14: 防水OK繃小 /片 | H14: =K3/3 -> 1 | I14: 16
B15: Nifedipine OROS (鈣離子阻斷劑) | C15: 30mg | D15: 每12小時1顆(30mg/12hr) | E15: =($K$3/2*$K$4)/8*6*E6 -> 0 | F15: 0 | G15: 透氣膠帶 /捲 | H15: =K4/3 -> 5.6666667 | I15: 2
B16: Dexamethasone (類固醇) | C16: 0.5mg | D16: 高山腦水腫:第一次8mg，之後4mg/6h (8mg：16顆口服或2瓶針劑； 4mg：8顆口服或1瓶針劑) 過敏性休克，經腎上腺素注射後：6-9mg/天，持續1-2天 | E16: =($K$3/2*1*$K$4/8)*8*(3)*E6 -> 0 | F16: 0 | G16: 防水透氣敷料 /片 | H16: =E19*2+E17*2 -> 4.25 | I16: 2
B17: Dexamethasone (類固醇針劑) | C17: 2.2mL/瓶 | E17: =($K$3/3+1)*E6 -> 0 | F17: 0 | G17: 酒精棉片 /片 | H17: =E20*2+E18*2 -> 0 | I17: 4
G18: 棉棒 /根 | H18: =K3*K4/5 -> 10.2 | I18: 10
B19: Epinephrine (腎上腺素針劑) | C19: 1 mL/瓶 | D19: 肌肉注射0.01mL/kg，每劑最多不超過0.5mL，每10~15分鐘一劑直到症狀緩解 (1瓶=1.0mL；共含1.0mg劑量) | E19: =($K$3/3*$K$4/8) -> 2.125 | F19: 4 | G19: 針筒 2mL/1mL | H19: =E17/3+E19/2 -> 1.0625 | I19: 46055
B20: 外用藥 | D20: 用法 | F20: 數量 | G20: 溫度計 /支 | H20: 1 | I20: 0
B21: 燙膚舒乳膏* | C21: \ | D21: 預防、治療細菌感染(大面積、深傷口；長程隊使用) | E21: 1 | F21: 1 | G21: 鎳子 /把 | H21: 1 | I21: 1
B22: 四環黴素 (眼藥膏) | C22: \ | D22: 預防、治療細菌感染 | E22: 1 | F22: 1 | G22: 剪刀 /把 | H22: 1 | I22: 1
B23: 強力施美* (抗組織胺) | C23: \ | D23: 皮膚搔癢、蕁麻疹、蚊蟲叮咬 | E23: 1 | F23: 1 | G23: Med 107 黃昱瑋 [三] CE 108 陳彥丰 [狼] MSE 109 沈豊淳 [星] FLL 109 曾薈芯 [狼] Med 116 嚴凱易 [狼]
B24: 非炎*¶ (消炎劑) | C24: \ | D24: 緩解肌肉發炎 (扭傷、骨折) | E24: 1 | F24: 1
B25: 優碘 | C25: \ | D25: 傷口消毒殺菌 | E25: 1 | F25: 1

Sheet 伙食表
A2: 隊伍名稱 | B2: 茶茶牙頓出西都驕溪 | G2: 人數 | H2: 17
A3: 隊伍天數、級數 | B3: 3D勘 | G3: 大廚
A4: 備註(討厭吃) | B4: 榴槤 納豆 芋頭 香菜香菜香菜 甲殼類海鮮過敏（蝦子、螃蟹） 午餐肉 豆製品 一切蕈類 各種肉、海鮮、茄子、秋葵、桂圓、芝麻、韭菜、青椒、洋蔥、牛奶被單獨出現、胡蘿蔔、苦瓜、芹菜、蔥薑蒜、香菜、紅棗 不吃辣 玉米（但多力多滋🉑）、米血 | G4: 總開銷
A5: 給腦袋風暴的地方 | B5: 1. 價格預算 數量克數 處理食材（烘乾 油封 先煮過 先洗過 先切過）營養均衡（蛋白質&澱粉…) 熱量 重量 大家的喜好過敏禁忌 好不好吃 食材腐敗問題 調味料們 器皿使用（如果要帶煎鍋必須得好好利用） 2. 在山下先想好料理順序：清理鍋子（辣炒年糕先再豆腐煲…）食材份量（好hardcore) 瓦斯 水 烹飪時間掌控
A6: 要記得帶 | B6: 最後公裝清點：鍋子、瓢、瓦斯、爐頭、瓦斯、公水大家要多少 最後私裝清點：鋁箔或鍋蓋、打火機、鋼杯餐具、廚房紙巾、大垃圾袋、醬料包、晚餐食材、宵夜食材（烤火食材）、早餐食材、粉包、砧板 山下處理方式 & 山上處理方式
A7: 營地 | B7: 餐餉 | C7: 餐點 | D7: 澱粉 | E7: 蛋豆魚肉 | F7: 蔬菜纖維 | G7: 水分飲品 | H7: 調味料 | I7: 備註
A8: C1 大廚：邱于馨 二廚：陳莉臻 | B8: 晚 | C8: 牛肋南瓜飯 | D8: 白飯、南瓜 | E8: 牛肋條、醉雞 | F8: 高麗菜、花椰菜、玉米筍 | G8: 2升 | H8: 鰹魚粉、印度咖哩
C9: 味噌豆腐湯 | E9: 板豆腐 | F9: 海帶芽 | G9: 2升 | H9: 味增
B11: 宵 | C11: 紅豆湯圓 | D11: 湯圓 | H11: 紅豆泥
C12: 香腸、杏鮑菇
B13: 早 | C13: 羅勒乳酪麵包 | D13: 麵包 | E13: 培根 | G13: 奶茶
A15: C2 大廚：張庭萱 二廚：李思誼 | B15: 晚 | C15: Pho | D15: 麵 | E15: 豬肉片 | F15: 青江菜、豆芽菜
C16: 玉米濃湯 | E16: 蛋 | G16: 2升
B18: 宵 | C18: 綠茶凍奶茶 | E18: 奶
B20: 早 | C20: 明太子起士黃瓜馬鈴薯吐司 | D20: 吐司 | E20: 起士明太子 | F20: 黃瓜 | G20: 美祿

Sheet 運動傷害社課筆記
B2: 骨頭 韌帶(只會一瞬間的事情) 肌腱(會慢慢累積然後爆炸)
B3: 預防/評估/治療/復健：了解復健才能知道怎麼預防
B4: 預防：熱身放鬆&肌力補強適度訓練(核心 小肌群補強)&正確動作與護具
B5: BAD：過度訓練、錯誤姿勢、不合適的用具和護具、肌力不平衡
B6: 常見骨骼肌傷害：拉傷、鐵腿(延遲性肌肉痠痛)、肌鍵炎或肌鍵病變
B7: 抽筋和拉傷的差別：肌肉疲勞或電解質失衡或中樞神經疲勞 恢復較快V.S 肌肉纖維撕裂可能伴隨瘀青 恢復較慢一定要復健
B8: 上肢：前上肩關節唇損傷(SLAP)、脫臼、網球軸
B9: 下肢：前十字韌帶斷裂、踝關節扭傷、應力性骨折
B10: 脊柱：椎間盤突出、脊椎側彎、閃到腰
B11: 前十字韌帶斷裂、半月板傷害(翻船)
B12: 外側踝扭傷(翻船)、高位扭傷、跟腱病變(阿基里斯腱)、足底筋膜炎(按摩球按足弓 小腿或痠的地方15秒痛 發炎的地方不要按)
B13: 熱傷害 熱痙攣 熱衰竭 熱中暑(移至陰涼處抬高雙腳不要強行補水)注意尿尿顏色
... B19: 外側踝扭傷 一律從內側開始包 八字包法6+8 睡覺的時候包著控制腫脹
